Workbook

Sheet Assumptions
A1: IMPOSTAZIONI ORARI LEZIONI
A3: Turno | B3: Orario Inizio | C3: Orario Fine
A4: Mattina | B4: 09:00 | C4: 13:00
A5: Pomeriggio | B5: 14:00 | C5: 18:00
A8: GIORNI DA ESCLUDERE (FESTIVITÀ E FERIE)
A10: 46023
A11: 46028
A12: 46118
A13: 46137
A14: 46143
A15: 46175
A16: 46244
A17: 46245
A18: 46246
A19: 46247
A20: 46248
A21: 46249
... A25: 46382

Sheet 2026
A1: ML5-05 Piano di dettaglio BCC | V1: Aggiornato il 03.12.2025
A2: ⚠️ IMPORTANTE: Le celle ROSSE indicano DUPLICATI (formatori/aule ripetuti nello stesso turno)
A4: JANUARY | C4: BCC | AB4: Fuori aula
A5: #REF!+1 | B5: Turno | C5: percorso | D5: Formatore 1 | E5: Formatore 2 | F5: Aula | G5: Attività | H5: Test | I5: percorso | J5: Formatore 1 | K5: Formatore 2 | L5: Aula | M5: Attività | N5: Test | O5: percorso | P5: Formatore 1 | Q5: Formatore 2 | R5: Aula | S5: Attività | T5: Test | U5: percorso | V5: Formatore 1 | W5: Formatore 2 | X5: Aula | Y5: Attività | Z5: Test | AA5: Fine corso | AB5: Form.1 | AC5: Att.Est.1 | AD5: Form.2 | AE5: Att.Est.2 | AF5: Form.3 | AG5: Att.Est.3 | AH5: Form.4 | AI5: Att.Est.4 | AJ5: Form.5 | AK5: Att.Est.5
A6: 46024 | B6: mattina
B7: Pomeriggio
A8: 46027 | B8: mattina
B9: Pomeriggio
A10: 46029 | B10: mattina
B11: Pomeriggio
A12: 46030 | B12: mattina
B13: Pomeriggio
A14: 46031 | B14: mattina
B15: Pomeriggio
A16: 46034 | B16: mattina
B17: Pomeriggio
A18: 46035 | B18: mattina
B19: Pomeriggio
A20: 46036 | B20: mattina
B21: Pomeriggio
A22: 46037 | B22: mattina
B23: Pomeriggio
A24: 46038 | B24: mattina
B25: Pomeriggio
A26: 46041 | B26: mattina
B27: Pomeriggio
A28: 46042 | B28: mattina
B29: Pomeriggio
A30: 46043 | B30: mattina
B31: Pomeriggio
A32: 46044 | B32: mattina
B33: Pomeriggio
A34: 46045 | B34: mattina
B35: Pomeriggio
A36: 46048 | B36: mattina
B37: Pomeriggio
A38: 46049 | B38: mattina
B39: Pomeriggio
A40: 46050 | B40: mattina
B41: Pomeriggio
...

Sheet AULE_1
A1: AULE DISPONIBILI
A2: 103
A3: 103a
A4: 108
A5: 110
A6: UFF

Sheet FORMATORI
A1: FORMATORI | B1: % | C1: n.giorni previsti | D1: Settimana non lavoro | E1: Festività e ferie | F1: n.giorni disponibili | G1: n.giorni svolti | H1: n.giorni rimanenti | I1: FORMATORI TEST
A2: CL | B2: 0.7 | C2: 155 | E2: 0 | F2: =C2-E2 | G2: =SUM(COUNTIF('2026'!D:D,A2),COUNTIF('2026'!E:E,A2),COUNTIF('2026'!J:J,A2),COUNTIF('2026'!K:K,A2),COUNTIF('2026'!P:P,A2),COUNTIF('2026'!Q:Q,A2),COUNTIF('2026'!V:V,A2),COUNTIF('2026'!W:W,A2),COUNTIF('2026'!AB:AB,A2),COUNTIF('2026'!AD:AD,A2),COUNTIF('2026'!AF:AF,A2),COUNTIF('2026'!AH:AH,A2),COUNTIF('2026'!AJ:AJ,A2)) | H2: =F2-G2 | I2: URS
A3: MC | B3: 0.5 | C3: 111 | D3: Mercoledì Mattina; Mercoledì pomeriggio | E3: 0 | F3: =C3-E3 | G3: =SUM(COUNTIF('2026'!D:D,A3),COUNTIF('2026'!E:E,A3),COUNTIF('2026'!J:J,A3),COUNTIF('2026'!K:K,A3),COUNTIF('2026'!P:P,A3),COUNTIF('2026'!Q:Q,A3),COUNTIF('2026'!V:V,A3),COUNTIF('2026'!W:W,A3),COUNTIF('2026'!AB:AB,A3),COUNTIF('2026'!AD:AD,A3),COUNTIF('2026'!AF:AF,A3),COUNTIF('2026'!AH:AH,A3),COUNTIF('2026'!AJ:AJ,A3)) | H3: =F3-G3 | I3: NIC
A4: LD | B4: 0.8 | C4: 177 | E4: 0 | F4: =C4-E4 | G4: =SUM(COUNTIF('2026'!D:D,A4),COUNTIF('2026'!E:E,A4),COUNTIF('2026'!J:J,A4),COUNTIF('2026'!K:K,A4),COUNTIF('2026'!P:P,A4),COUNTIF('2026'!Q:Q,A4),COUNTIF('2026'!V:V,A4),COUNTIF('2026'!W:W,A4),COUNTIF('2026'!AB:AB,A4),COUNTIF('2026'!AD:AD,A4),COUNTIF('2026'!AF:AF,A4),COUNTIF('2026'!AH:AH,A4),COUNTIF('2026'!AJ:AJ,A4)) | H4: =F4-G4 | I4: MIT
A5: EP | B5: 0.9 | C5: 199 | E5: 0 | F5: =C5-E5 | G5: =SUM(COUNTIF('2026'!D:D,A5),COUNTIF('2026'!E:E,A5),COUNTIF('2026'!J:J,A5),COUNTIF('2026'!K:K,A5),COUNTIF('2026'!P:P,A5),COUNTIF('2026'!Q:Q,A5),COUNTIF('2026'!V:V,A5),COUNTIF('2026'!W:W,A5),COUNTIF('2026'!AB:AB,A5),COUNTIF('2026'!AD:AD,A5),COUNTIF('2026'!AF:AF,A5),COUNTIF('2026'!AH:AH,A5),COUNTIF('2026'!AJ:AJ,A5)) | H5: =F5-G5 | I5: MON
A6: IP | B6: 0.9 | C6: 199 | E6: 0 | F6: =C6-E6 | G6: =SUM(COUNTIF('2026'!D:D,A6),COUNTIF('2026'!E:E,A6),COUNTIF('2026'!J:J,A6),COUNTIF('2026'!K:K,A6),COUNTIF('2026'!P:P,A6),COUNTIF('2026'!Q:Q,A6),COUNTIF('2026'!V:V,A6),COUNTIF('2026'!W:W,A6),COUNTIF('2026'!AB:AB,A6),COUNTIF('2026'!AD:AD,A6),COUNTIF('2026'!AF:AF,A6),COUNTIF('2026'!AH:AH,A6),COUNTIF('2026'!AJ:AJ,A6)) | H6: =F6-G6 | I6: WER
A7: FB | B7: 0.8 | C7: 177 | E7: 0 | F7: =C7-E7 | G7: =SUM(COUNTIF('2026'!D:D,A7),COUNTIF('2026'!E:E,A7),COUNTIF('2026'!J:J,A7),COUNTIF('2026'!K:K,A7),COUNTIF('2026'!P:P,A7),COUNTIF('2026'!Q:Q,A7),COUNTIF('2026'!V:V,A7),COUNTIF('2026'!W:W,A7),COUNTIF('2026'!AB:AB,A7),COUNTIF('2026'!AD:AD,A7),COUNTIF('2026'!AF:AF,A7),COUNTIF('2026'!AH:AH,A7),COUNTIF('2026'!AJ:AJ,A7)) | H7: =F7-G7
A8: GZ | B8: 0.8 | C8: 177 | E8: 0 | F8: =C8-E8 | G8: =SUM(COUNTIF('2026'!D:D,A8),COUNTIF('2026'!E:E,A8),COUNTIF('2026'!J:J,A8),COUNTIF('2026'!K:K,A8),COUNTIF('2026'!P:P,A8),COUNTIF('2026'!Q:Q,A8),COUNTIF('2026'!V:V,A8),COUNTIF('2026'!W:W,A8),COUNTIF('2026'!AB:AB,A8),COUNTIF('2026'!AD:AD,A8),COUNTIF('2026'!AF:AF,A8),COUNTIF('2026'!AH:AH,A8),COUNTIF('2026'!AJ:AJ,A8)) | H8: =F8-G8
A9: DC | B9: 0.4 | C9: 88 | D9: Mercoledì Mattina; Mercoledì pomeriggio | E9: 0 | F9: =C9-E9 | G9: =SUM(COUNTIF('2026'!D:D,A9),COUNTIF('2026'!E:E,A9),COUNTIF('2026'!J:J,A9),COUNTIF('2026'!K:K,A9),COUNTIF('2026'!P:P,A9),COUNTIF('2026'!Q:Q,A9),COUNTIF('2026'!V:V,A9),COUNTIF('2026'!W:W,A9),COUNTIF('2026'!AB:AB,A9),COUNTIF('2026'!AD:AD,A9),COUNTIF('2026'!AF:AF,A9),COUNTIF('2026'!AH:AH,A9),COUNTIF('2026'!AJ:AJ,A9)) | H9: =F9-G9
A51: CL | I51: URS
A52: MC | I52: NIC
A53: LD | I53: MIT
A54: EP | I54: MON
A55: IP | I55: WER
A56: FB
A57: GZ
A58: DC

Sheet CONTROLLO_AULE
A1: AULA | B1: DESCRIZIONE | C1: ATTIVITÀ COMPATIBILI | E1: 103_ATT | F1: 103a_ATT | G1: 108_ATT | H1: 110_ATT | I1: UFF_ATT
A2: 103 | B2: Aula 103 | C2: AULA
C3: DIGI
C4: CV
C5: CS
C6: RA
C7: TT
C8: TI
A10: 103a | B10: Aula 103a | C10: AULA
C11: DIGI
C12: CV
C13: CS
C14: RA
C15: TT
C16: TI
A18: 108 | B18: Aula 108 | C18: AULA
C19: CV
C20: CS
C21: RA
A23: 110 | B23: Aula 110 | C23: AULA
C24: CV
C25: CS
C26: RA
A28: UFF | B28: Aula UFF | C28: UFF
C29: COL
C30: C
A50: 103 | C50: AULA | D50: RIUNIONE | E50: AULA | F50: AULA | G50: AULA | H50: AULA | I50: UFF
A51: 103a | C51: C | D51: FORMAZIONE | E51: DIGI | F51: DIGI | G51: CV | H51: CV | I51: COL
A52: 108 | C52: COL | D52: CONSULENZA | E52: CV | F52: CV | G52: CS | H52: CS | I52: C
A53: 110 | C53: CS | D53: AUDIT | E53: CS | F53: CS | G53: RA | H53: RA
A54: UFF | C54: CV | D54: ALTRO | E54: RA | F54: RA
C55: DIGI | E55: TT | F55: TT
C56: RA | E56: TI | F56: TI
C57: TI
C58: TT
C59: UFF

Sheet ATT. ESTERNE
A1: CONFIGURAZIONE ATTIVITÀ ESTERNE
A3: Codice | B3: Descrizione | C3: Note
A4: Amm | B4: Amministrazione | C4: Attività amministrative
A5: IA | B5: Intelligenza Artificiale | C5: Corsi IA
A6: AI | B6: Corso AI | C6: Corso specifico AI
A7: Dig | B7: Digitale | C7: Attività digitali
A8: P1 | B8: Progetto 1 | C8: Modificabile
A9: P2 | B9: Progetto 2 | C9: Modificabile
A10: P3 | B10: Progetto 3 | C10: Modificabile
A11: P4 | B11: Progetto 4 | C11: Modificabile
A12: P5 | B12: Progetto 5 | C12: Modificabile
A15: 💡 ISTRUZIONI:
A16: 1. Modifica la colonna "Descrizione" per i progetti P1-P5
A17: 2. Esempio: P1 = "Progetto Sostenibilità"
A18: 3. Le modifiche appariranno automaticamente nei PDF dei formatori
B50: Amm
B51: IA
B52: AI
B53: Dig
B54: P1
B55: P2
B56: P3
B57: P4
B58: P5
